[2024-05-29T00:34:14.896+0000] {local_task_job_runner.py:120} INFO - ::group::Pre task execution logs
[2024-05-29T00:34:14.938+0000] {taskinstance.py:2076} INFO - Dependencies all met for dep_context=non-requeueable deps ti=<TaskInstance: dados_climaticos_estruturados.criar_pasta scheduled__2024-05-18T03:45:00+00:00 [queued]>
[2024-05-29T00:34:14.954+0000] {taskinstance.py:2076} INFO - Dependencies all met for dep_context=requeueable deps ti=<TaskInstance: dados_climaticos_estruturados.criar_pasta scheduled__2024-05-18T03:45:00+00:00 [queued]>
[2024-05-29T00:34:14.958+0000] {taskinstance.py:2306} INFO - Starting attempt 1 of 1
[2024-05-29T00:34:14.982+0000] {taskinstance.py:2330} INFO - Executing <Task(PythonOperator): criar_pasta> on 2024-05-18 03:45:00+00:00
[2024-05-29T00:34:14.992+0000] {warnings.py:110} WARNING - /home/***/.local/lib/python3.12/site-packages/***/task/task_runner/standard_task_runner.py:61: DeprecationWarning: This process (pid=1068) is multi-threaded, use of fork() may lead to deadlocks in the child.
  pid = os.fork()

[2024-05-29T00:34:14.995+0000] {standard_task_runner.py:63} INFO - Started process 1087 to run task
[2024-05-29T00:34:14.995+0000] {standard_task_runner.py:90} INFO - Running: ['***', 'tasks', 'run', 'dados_climaticos_estruturados', 'criar_pasta', 'scheduled__2024-05-18T03:45:00+00:00', '--job-id', '404', '--raw', '--subdir', 'DAGS_FOLDER/weather/custom_dags/dados_climaticos_estruturados.py', '--cfg-path', '/tmp/tmp4mryu7rb']
[2024-05-29T00:34:14.997+0000] {standard_task_runner.py:91} INFO - Job 404: Subtask criar_pasta
[2024-05-29T00:34:15.075+0000] {task_command.py:426} INFO - Running <TaskInstance: dados_climaticos_estruturados.criar_pasta scheduled__2024-05-18T03:45:00+00:00 [running]> on host 0473b835f7f4
[2024-05-29T00:34:15.204+0000] {taskinstance.py:2648} INFO - Exporting env vars: AIRFLOW_CTX_DAG_OWNER='***' AIRFLOW_CTX_DAG_ID='dados_climaticos_estruturados' AIRFLOW_CTX_TASK_ID='criar_pasta' AIRFLOW_CTX_EXECUTION_DATE='2024-05-18T03:45:00+00:00' AIRFLOW_CTX_TRY_NUMBER='1' AIRFLOW_CTX_DAG_RUN_ID='scheduled__2024-05-18T03:45:00+00:00'
[2024-05-29T00:34:15.207+0000] {taskinstance.py:430} INFO - ::endgroup::
[2024-05-29T00:34:15.209+0000] {taskinstance.py:441} INFO - ::group::Post task execution logs
[2024-05-29T00:34:15.211+0000] {taskinstance.py:2905} ERROR - Task failed with exception
Traceback (most recent call last):
  File "/home/airflow/.local/lib/python3.12/site-packages/airflow/models/taskinstance.py", line 465, in _execute_task
    result = _execute_callable(context=context, **execute_callable_kwargs)
             ^^^^^^^^^^^^^^^^^^^^^^^^^^^^^^^^^^^^^^^^^^^^^^^^^^^^^^^^^^^^^
  File "/home/airflow/.local/lib/python3.12/site-packages/airflow/models/taskinstance.py", line 432, in _execute_callable
    return execute_callable(context=context, **execute_callable_kwargs)
           ^^^^^^^^^^^^^^^^^^^^^^^^^^^^^^^^^^^^^^^^^^^^^^^^^^^^^^^^^^^^
  File "/home/airflow/.local/lib/python3.12/site-packages/airflow/models/baseoperator.py", line 400, in wrapper
    return func(self, *args, **kwargs)
           ^^^^^^^^^^^^^^^^^^^^^^^^^^^
  File "/home/airflow/.local/lib/python3.12/site-packages/airflow/operators/python.py", line 235, in execute
    return_value = self.execute_callable()
                   ^^^^^^^^^^^^^^^^^^^^^^^
  File "/home/airflow/.local/lib/python3.12/site-packages/airflow/operators/python.py", line 252, in execute_callable
    return self.python_callable(*self.op_args, **self.op_kwargs)
           ^^^^^^^^^^^^^^^^^^^^^^^^^^^^^^^^^^^^^^^^^^^^^^^^^^^^^
  File "/opt/airflow/dags/weather/custom_dags/dados_climaticos_estruturados.py", line 18, in pegar_data_e_criar_pasta
    Path(caminho).mkdir(parents=True, exist_ok=True)
    ^^^^
NameError: name 'Path' is not defined
[2024-05-29T00:34:15.227+0000] {taskinstance.py:1206} INFO - Marking task as FAILED. dag_id=dados_climaticos_estruturados, task_id=criar_pasta, run_id=scheduled__2024-05-18T03:45:00+00:00, execution_date=20240518T034500, start_date=20240529T003414, end_date=20240529T003415
[2024-05-29T00:34:15.251+0000] {standard_task_runner.py:110} ERROR - Failed to execute job 404 for task criar_pasta (name 'Path' is not defined; 1087)
[2024-05-29T00:34:15.305+0000] {local_task_job_runner.py:240} INFO - Task exited with return code 1
[2024-05-29T00:34:15.319+0000] {local_task_job_runner.py:222} INFO - ::endgroup::
