[2024-06-05T01:21:16.974+0000] {local_task_job_runner.py:120} INFO - ::group::Pre task execution logs
[2024-06-05T01:21:17.011+0000] {taskinstance.py:2076} INFO - Dependencies all met for dep_context=non-requeueable deps ti=<TaskInstance: dados_climaticos_estruturados.extrair_dados scheduled__2024-06-03T11:00:00+00:00 [queued]>
[2024-06-05T01:21:17.028+0000] {taskinstance.py:2076} INFO - Dependencies all met for dep_context=requeueable deps ti=<TaskInstance: dados_climaticos_estruturados.extrair_dados scheduled__2024-06-03T11:00:00+00:00 [queued]>
[2024-06-05T01:21:17.029+0000] {taskinstance.py:2306} INFO - Starting attempt 1 of 1
[2024-06-05T01:21:17.047+0000] {taskinstance.py:2330} INFO - Executing <Task(PythonOperator): extrair_dados> on 2024-06-03 11:00:00+00:00
[2024-06-05T01:21:17.058+0000] {warnings.py:110} WARNING - /home/***/.local/lib/python3.12/site-packages/***/task/task_runner/standard_task_runner.py:61: DeprecationWarning: This process (pid=10035) is multi-threaded, use of fork() may lead to deadlocks in the child.
  pid = os.fork()

[2024-06-05T01:21:17.060+0000] {standard_task_runner.py:63} INFO - Started process 10042 to run task
[2024-06-05T01:21:17.060+0000] {standard_task_runner.py:90} INFO - Running: ['***', 'tasks', 'run', 'dados_climaticos_estruturados', 'extrair_dados', 'scheduled__2024-06-03T11:00:00+00:00', '--job-id', '3599', '--raw', '--subdir', 'DAGS_FOLDER/weather/custom_dags/dados_climaticos_estruturados.py', '--cfg-path', '/tmp/tmpycxvzzea']
[2024-06-05T01:21:17.064+0000] {standard_task_runner.py:91} INFO - Job 3599: Subtask extrair_dados
[2024-06-05T01:21:17.126+0000] {task_command.py:426} INFO - Running <TaskInstance: dados_climaticos_estruturados.extrair_dados scheduled__2024-06-03T11:00:00+00:00 [running]> on host 6665b0710315
[2024-06-05T01:21:17.253+0000] {taskinstance.py:2648} INFO - Exporting env vars: AIRFLOW_CTX_DAG_OWNER='***' AIRFLOW_CTX_DAG_ID='dados_climaticos_estruturados' AIRFLOW_CTX_TASK_ID='extrair_dados' AIRFLOW_CTX_EXECUTION_DATE='2024-06-03T11:00:00+00:00' AIRFLOW_CTX_TRY_NUMBER='1' AIRFLOW_CTX_DAG_RUN_ID='scheduled__2024-06-03T11:00:00+00:00'
[2024-06-05T01:21:17.255+0000] {taskinstance.py:430} INFO - ::endgroup::
[2024-06-05T01:21:18.177+0000] {taskinstance.py:441} INFO - ::group::Post task execution logs
[2024-06-05T01:21:18.178+0000] {taskinstance.py:2905} ERROR - Task failed with exception
Traceback (most recent call last):
  File "/home/airflow/.local/lib/python3.12/site-packages/airflow/models/taskinstance.py", line 465, in _execute_task
    result = _execute_callable(context=context, **execute_callable_kwargs)
             ^^^^^^^^^^^^^^^^^^^^^^^^^^^^^^^^^^^^^^^^^^^^^^^^^^^^^^^^^^^^^
  File "/home/airflow/.local/lib/python3.12/site-packages/airflow/models/taskinstance.py", line 432, in _execute_callable
    return execute_callable(context=context, **execute_callable_kwargs)
           ^^^^^^^^^^^^^^^^^^^^^^^^^^^^^^^^^^^^^^^^^^^^^^^^^^^^^^^^^^^^
  File "/home/airflow/.local/lib/python3.12/site-packages/airflow/models/baseoperator.py", line 400, in wrapper
    return func(self, *args, **kwargs)
           ^^^^^^^^^^^^^^^^^^^^^^^^^^^
  File "/home/airflow/.local/lib/python3.12/site-packages/airflow/operators/python.py", line 235, in execute
    return_value = self.execute_callable()
                   ^^^^^^^^^^^^^^^^^^^^^^^
  File "/home/airflow/.local/lib/python3.12/site-packages/airflow/operators/python.py", line 252, in execute_callable
    return self.python_callable(*self.op_args, **self.op_kwargs)
           ^^^^^^^^^^^^^^^^^^^^^^^^^^^^^^^^^^^^^^^^^^^^^^^^^^^^^
  File "/opt/airflow/dags/weather/etl/extract.py", line 13, in extrair_dados
    dados = pd.read_csv(url)
            ^^^^^^^^^^^^^^^^
  File "/home/airflow/.local/lib/python3.12/site-packages/pandas/io/parsers/readers.py", line 1026, in read_csv
    return _read(filepath_or_buffer, kwds)
           ^^^^^^^^^^^^^^^^^^^^^^^^^^^^^^^
  File "/home/airflow/.local/lib/python3.12/site-packages/pandas/io/parsers/readers.py", line 620, in _read
    parser = TextFileReader(filepath_or_buffer, **kwds)
             ^^^^^^^^^^^^^^^^^^^^^^^^^^^^^^^^^^^^^^^^^^
  File "/home/airflow/.local/lib/python3.12/site-packages/pandas/io/parsers/readers.py", line 1620, in __init__
    self._engine = self._make_engine(f, self.engine)
                   ^^^^^^^^^^^^^^^^^^^^^^^^^^^^^^^^^
  File "/home/airflow/.local/lib/python3.12/site-packages/pandas/io/parsers/readers.py", line 1880, in _make_engine
    self.handles = get_handle(
                   ^^^^^^^^^^^
  File "/home/airflow/.local/lib/python3.12/site-packages/pandas/io/common.py", line 728, in get_handle
    ioargs = _get_filepath_or_buffer(
             ^^^^^^^^^^^^^^^^^^^^^^^^
  File "/home/airflow/.local/lib/python3.12/site-packages/pandas/io/common.py", line 384, in _get_filepath_or_buffer
    with urlopen(req_info) as req:
         ^^^^^^^^^^^^^^^^^
  File "/home/airflow/.local/lib/python3.12/site-packages/pandas/io/common.py", line 289, in urlopen
    return urllib.request.urlopen(*args, **kwargs)
           ^^^^^^^^^^^^^^^^^^^^^^^^^^^^^^^^^^^^^^^
  File "/usr/local/lib/python3.12/urllib/request.py", line 215, in urlopen
    return opener.open(url, data, timeout)
           ^^^^^^^^^^^^^^^^^^^^^^^^^^^^^^^
  File "/usr/local/lib/python3.12/urllib/request.py", line 521, in open
    response = meth(req, response)
               ^^^^^^^^^^^^^^^^^^^
  File "/usr/local/lib/python3.12/urllib/request.py", line 630, in http_response
    response = self.parent.error(
               ^^^^^^^^^^^^^^^^^^
  File "/usr/local/lib/python3.12/urllib/request.py", line 559, in error
    return self._call_chain(*args)
           ^^^^^^^^^^^^^^^^^^^^^^^
  File "/usr/local/lib/python3.12/urllib/request.py", line 492, in _call_chain
    result = func(*args)
             ^^^^^^^^^^^
  File "/usr/local/lib/python3.12/urllib/request.py", line 639, in http_error_default
    raise HTTPError(req.full_url, code, msg, hdrs, fp)
urllib.error.HTTPError: HTTP Error 401: 
[2024-06-05T01:21:18.195+0000] {taskinstance.py:1206} INFO - Marking task as FAILED. dag_id=dados_climaticos_estruturados, task_id=extrair_dados, run_id=scheduled__2024-06-03T11:00:00+00:00, execution_date=20240603T110000, start_date=20240605T012117, end_date=20240605T012118
[2024-06-05T01:21:18.216+0000] {standard_task_runner.py:110} ERROR - Failed to execute job 3599 for task extrair_dados (HTTP Error 401: ; 10042)
[2024-06-05T01:21:18.269+0000] {local_task_job_runner.py:240} INFO - Task exited with return code 1
[2024-06-05T01:21:18.293+0000] {taskinstance.py:3498} INFO - 0 downstream tasks scheduled from follow-on schedule check
[2024-06-05T01:21:18.296+0000] {local_task_job_runner.py:222} INFO - ::endgroup::
