[2024-05-29T00:35:12.755+0000] {local_task_job_runner.py:120} INFO - ::group::Pre task execution logs
[2024-05-29T00:35:12.799+0000] {taskinstance.py:2076} INFO - Dependencies all met for dep_context=non-requeueable deps ti=<TaskInstance: dados_climaticos_estruturados.criar_pasta scheduled__2024-05-18T10:25:00+00:00 [queued]>
[2024-05-29T00:35:12.814+0000] {taskinstance.py:2076} INFO - Dependencies all met for dep_context=requeueable deps ti=<TaskInstance: dados_climaticos_estruturados.criar_pasta scheduled__2024-05-18T10:25:00+00:00 [queued]>
[2024-05-29T00:35:12.815+0000] {taskinstance.py:2306} INFO - Starting attempt 1 of 1
[2024-05-29T00:35:12.840+0000] {taskinstance.py:2330} INFO - Executing <Task(PythonOperator): criar_pasta> on 2024-05-18 10:25:00+00:00
[2024-05-29T00:35:12.856+0000] {warnings.py:110} WARNING - /home/***/.local/lib/python3.12/site-packages/***/task/task_runner/standard_task_runner.py:61: DeprecationWarning: This process (pid=1330) is multi-threaded, use of fork() may lead to deadlocks in the child.
  pid = os.fork()

[2024-05-29T00:35:12.860+0000] {standard_task_runner.py:63} INFO - Started process 1347 to run task
[2024-05-29T00:35:12.864+0000] {standard_task_runner.py:90} INFO - Running: ['***', 'tasks', 'run', 'dados_climaticos_estruturados', 'criar_pasta', 'scheduled__2024-05-18T10:25:00+00:00', '--job-id', '485', '--raw', '--subdir', 'DAGS_FOLDER/weather/custom_dags/dados_climaticos_estruturados.py', '--cfg-path', '/tmp/tmpjbcn8cze']
[2024-05-29T00:35:12.869+0000] {standard_task_runner.py:91} INFO - Job 485: Subtask criar_pasta
[2024-05-29T00:35:13.006+0000] {task_command.py:426} INFO - Running <TaskInstance: dados_climaticos_estruturados.criar_pasta scheduled__2024-05-18T10:25:00+00:00 [running]> on host 0473b835f7f4
[2024-05-29T00:35:13.273+0000] {taskinstance.py:2648} INFO - Exporting env vars: AIRFLOW_CTX_DAG_OWNER='***' AIRFLOW_CTX_DAG_ID='dados_climaticos_estruturados' AIRFLOW_CTX_TASK_ID='criar_pasta' AIRFLOW_CTX_EXECUTION_DATE='2024-05-18T10:25:00+00:00' AIRFLOW_CTX_TRY_NUMBER='1' AIRFLOW_CTX_DAG_RUN_ID='scheduled__2024-05-18T10:25:00+00:00'
[2024-05-29T00:35:13.286+0000] {taskinstance.py:430} INFO - ::endgroup::
[2024-05-29T00:35:13.295+0000] {taskinstance.py:441} INFO - ::group::Post task execution logs
[2024-05-29T00:35:13.298+0000] {taskinstance.py:2905} ERROR - Task failed with exception
Traceback (most recent call last):
  File "/home/airflow/.local/lib/python3.12/site-packages/airflow/models/taskinstance.py", line 465, in _execute_task
    result = _execute_callable(context=context, **execute_callable_kwargs)
             ^^^^^^^^^^^^^^^^^^^^^^^^^^^^^^^^^^^^^^^^^^^^^^^^^^^^^^^^^^^^^
  File "/home/airflow/.local/lib/python3.12/site-packages/airflow/models/taskinstance.py", line 432, in _execute_callable
    return execute_callable(context=context, **execute_callable_kwargs)
           ^^^^^^^^^^^^^^^^^^^^^^^^^^^^^^^^^^^^^^^^^^^^^^^^^^^^^^^^^^^^
  File "/home/airflow/.local/lib/python3.12/site-packages/airflow/models/baseoperator.py", line 400, in wrapper
    return func(self, *args, **kwargs)
           ^^^^^^^^^^^^^^^^^^^^^^^^^^^
  File "/home/airflow/.local/lib/python3.12/site-packages/airflow/operators/python.py", line 235, in execute
    return_value = self.execute_callable()
                   ^^^^^^^^^^^^^^^^^^^^^^^
  File "/home/airflow/.local/lib/python3.12/site-packages/airflow/operators/python.py", line 252, in execute_callable
    return self.python_callable(*self.op_args, **self.op_kwargs)
           ^^^^^^^^^^^^^^^^^^^^^^^^^^^^^^^^^^^^^^^^^^^^^^^^^^^^^
  File "/opt/airflow/dags/weather/custom_dags/dados_climaticos_estruturados.py", line 18, in pegar_data_e_criar_pasta
    Path(caminho).mkdir(parents=True, exist_ok=True)
    ^^^^
NameError: name 'Path' is not defined
[2024-05-29T00:35:13.360+0000] {taskinstance.py:1206} INFO - Marking task as FAILED. dag_id=dados_climaticos_estruturados, task_id=criar_pasta, run_id=scheduled__2024-05-18T10:25:00+00:00, execution_date=20240518T102500, start_date=20240529T003512, end_date=20240529T003513
[2024-05-29T00:35:13.451+0000] {standard_task_runner.py:110} ERROR - Failed to execute job 485 for task criar_pasta (name 'Path' is not defined; 1347)
[2024-05-29T00:35:13.513+0000] {local_task_job_runner.py:240} INFO - Task exited with return code 1
[2024-05-29T00:35:13.541+0000] {local_task_job_runner.py:222} INFO - ::endgroup::
