[2024-05-21T00:02:05.474+0000] {local_task_job_runner.py:120} INFO - ::group::Pre task execution logs
[2024-05-21T00:02:05.507+0000] {taskinstance.py:2076} INFO - Dependencies all met for dep_context=non-requeueable deps ti=<TaskInstance: dados_climaticos_estruturados.criar_pasta scheduled__2024-05-18T00:40:00+00:00 [queued]>
[2024-05-21T00:02:05.520+0000] {taskinstance.py:2076} INFO - Dependencies all met for dep_context=requeueable deps ti=<TaskInstance: dados_climaticos_estruturados.criar_pasta scheduled__2024-05-18T00:40:00+00:00 [queued]>
[2024-05-21T00:02:05.521+0000] {taskinstance.py:2306} INFO - Starting attempt 1 of 1
[2024-05-21T00:02:05.541+0000] {taskinstance.py:2330} INFO - Executing <Task(PythonOperator): criar_pasta> on 2024-05-18 00:40:00+00:00
[2024-05-21T00:02:05.551+0000] {warnings.py:110} WARNING - /home/***/.local/lib/python3.12/site-packages/***/task/task_runner/standard_task_runner.py:61: DeprecationWarning: This process (pid=533) is multi-threaded, use of fork() may lead to deadlocks in the child.
  pid = os.fork()

[2024-05-21T00:02:05.553+0000] {standard_task_runner.py:63} INFO - Started process 552 to run task
[2024-05-21T00:02:05.554+0000] {standard_task_runner.py:90} INFO - Running: ['***', 'tasks', 'run', 'dados_climaticos_estruturados', 'criar_pasta', 'scheduled__2024-05-18T00:40:00+00:00', '--job-id', '5697', '--raw', '--subdir', 'DAGS_FOLDER/weather/custom_dags/dados_climaticos_estruturados.py', '--cfg-path', '/tmp/tmp0ptumpfd']
[2024-05-21T00:02:05.555+0000] {standard_task_runner.py:91} INFO - Job 5697: Subtask criar_pasta
[2024-05-21T00:02:05.632+0000] {task_command.py:426} INFO - Running <TaskInstance: dados_climaticos_estruturados.criar_pasta scheduled__2024-05-18T00:40:00+00:00 [running]> on host 1078a6fe2d09
[2024-05-21T00:02:05.754+0000] {taskinstance.py:2648} INFO - Exporting env vars: AIRFLOW_CTX_DAG_OWNER='***' AIRFLOW_CTX_DAG_ID='dados_climaticos_estruturados' AIRFLOW_CTX_TASK_ID='criar_pasta' AIRFLOW_CTX_EXECUTION_DATE='2024-05-18T00:40:00+00:00' AIRFLOW_CTX_TRY_NUMBER='1' AIRFLOW_CTX_DAG_RUN_ID='scheduled__2024-05-18T00:40:00+00:00'
[2024-05-21T00:02:05.757+0000] {taskinstance.py:430} INFO - ::endgroup::
[2024-05-21T00:02:05.758+0000] {taskinstance.py:441} INFO - ::group::Post task execution logs
[2024-05-21T00:02:05.759+0000] {taskinstance.py:2905} ERROR - Task failed with exception
Traceback (most recent call last):
  File "/home/airflow/.local/lib/python3.12/site-packages/airflow/models/taskinstance.py", line 465, in _execute_task
    result = _execute_callable(context=context, **execute_callable_kwargs)
             ^^^^^^^^^^^^^^^^^^^^^^^^^^^^^^^^^^^^^^^^^^^^^^^^^^^^^^^^^^^^^
  File "/home/airflow/.local/lib/python3.12/site-packages/airflow/models/taskinstance.py", line 432, in _execute_callable
    return execute_callable(context=context, **execute_callable_kwargs)
           ^^^^^^^^^^^^^^^^^^^^^^^^^^^^^^^^^^^^^^^^^^^^^^^^^^^^^^^^^^^^
  File "/home/airflow/.local/lib/python3.12/site-packages/airflow/models/baseoperator.py", line 400, in wrapper
    return func(self, *args, **kwargs)
           ^^^^^^^^^^^^^^^^^^^^^^^^^^^
  File "/home/airflow/.local/lib/python3.12/site-packages/airflow/operators/python.py", line 235, in execute
    return_value = self.execute_callable()
                   ^^^^^^^^^^^^^^^^^^^^^^^
  File "/home/airflow/.local/lib/python3.12/site-packages/airflow/operators/python.py", line 252, in execute_callable
    return self.python_callable(*self.op_args, **self.op_kwargs)
           ^^^^^^^^^^^^^^^^^^^^^^^^^^^^^^^^^^^^^^^^^^^^^^^^^^^^^
  File "/opt/airflow/dags/weather/custom_dags/dados_climaticos_estruturados.py", line 19, in pegar_data_e_criar_pasta
    Path(caminho).mkdir(parents=True, exist_ok=True)
    ^^^^
NameError: name 'Path' is not defined
[2024-05-21T00:02:05.776+0000] {taskinstance.py:1206} INFO - Marking task as FAILED. dag_id=dados_climaticos_estruturados, task_id=criar_pasta, run_id=scheduled__2024-05-18T00:40:00+00:00, execution_date=20240518T004000, start_date=20240521T000205, end_date=20240521T000205
[2024-05-21T00:02:05.807+0000] {standard_task_runner.py:110} ERROR - Failed to execute job 5697 for task criar_pasta (name 'Path' is not defined; 552)
[2024-05-21T00:02:05.861+0000] {local_task_job_runner.py:240} INFO - Task exited with return code 1
[2024-05-21T00:02:05.884+0000] {local_task_job_runner.py:222} INFO - ::endgroup::
